Workbook
Name Slicer_Product: #N/A
Name Slicer_Region: #N/A

Sheet Sheet1
A1: Date | B1: Region | C1: Product | D1: Quantity | E1: UnitPrice | F1: StoreLocation | G1: CustomerType | H1: Discount | I1: Salesperson | J1: TotalPrice | K1: PaymentMethod | L1: Promotion | M1: Returned | N1: OrderID | O1: CustomerName | P1: ShippingCost | Q1: OrderDate | R1: DeliveryDate | S1: RegionManager | T1: Month
A2: 44980 | B2: East | C2: Laptop | D2: 14 | E2: 163.6 | F2: Store B | G2: Wholesale | H2: 0 | I2: Eva | J2: 2290.4 | K2: Online | L2: FREESHIP | M2: 0 | N2: REG100000 | O2: Cust 6583 | P2: 43.34 | Q2: 44980 | R2: 44984 | S2: Eric | T2: =TEXT(A2,"mmmm") -> February
A3: 45645 | B3: South | C3: Phone | D3: 1 | E3: 544.01 | F3: Store A | G3: Retail | H3: 0 | I3: Alice | J3: 544.01 | K3: Gift Card | L3: SAVE10 | M3: 0 | N3: REG100001 | O3: Cust 2144 | P3: 5.3 | Q3: 45645 | R3: 45654 | S3: Sophie | T3: =TEXT(A3,"mmmm") -> December
A4: 45056 | B4: North | C4: Desk | D4: 14 | E4: 346.18 | F4: Store B | G4: Wholesale | H4: 0.1 | I4: Alice | J4: 4361.868 | K4: Online | L4: WINTER15 | M4: 0 | N4: REG100002 | O4: Cust 5998 | P4: 20.46 | Q4: 45056 | R4: 45065 | S4: Ryan | T4: =TEXT(A4,"mmmm") -> May
A5: 45714 | B5: Central | C5: Chair | D5: 18 | E5: 384.82 | F5: Store A | G5: Wholesale | H5: 0.15 | I5: Frank | J5: 5887.746 | K5: Gift Card | L5: FREESHIP | M5: 0 | N5: REG100003 | O5: Cust 7136 | P5: 27.95 | Q5: 45714 | R5: 45718 | S5: Cameron | T5: =TEXT(A5,"mmmm") -> February
A6: 45101 | B6: East | C6: Desk | D6: 18 | E6: 237.76 | F6: Store C | G6: Retail | H6: 0 | I6: Carlos | J6: 4279.68 | K6: Online | L6: SAVE10 | M6: 0 | N6: REG100004 | O6: Cust 6506 | P6: 5.73 | Q6: 45101 | R6: 45104 | S6: Eric | T6: =TEXT(A6,"mmmm") -> June
A7: 45342 | B7: Central | C7: Monitor | D7: 2 | E7: 385.09 | F7: Store D | G7: Wholesale | H7: 0.15 | I7: Diana | J7: 654.653 | K7: Credit Card | M7: 0 | N7: REG100005 | O7: Cust 3909 | P7: 11.92 | Q7: 45342 | R7: 45352 | S7: Cameron | T7: =TEXT(A7,"mmmm") -> February
A8: 44937 | B8: South | C8: Chair | D8: 7 | E8: 17.5 | F8: Store C | G8: Retail | H8: 0.1 | I8: Alice | J8: 110.25 | K8: Debit Card | L8: WINTER15 | M8: 0 | N8: REG100006 | O8: Cust 7887 | P8: 5.02 | Q8: 44937 | R8: 44940 | S8: Sophie | T8: =TEXT(A8,"mmmm") -> January
A9: 44935 | B9: Central | C9: Chair | D9: 3 | E9: 330.22 | F9: Store C | G9: Wholesale | H9: 0.15 | I9: Carlos | J9: 842.061 | K9: Cash | M9: 0 | N9: REG100007 | O9: Cust 5301 | P9: 48.01 | Q9: 44935 | R9: 44937 | S9: Cameron | T9: =TEXT(A9,"mmmm") -> January
A10: 45581 | B10: South | C10: Chair | D10: 3 | E10: 432.04 | F10: Store D | G10: Wholesale | H10: 0.05 | I10: Bob | J10: 1231.314 | K10: Debit Card | L10: FREESHIP | M10: 1 | N10: REG100008 | O10: Cust 2284 | P10: 42.11 | Q10: 45581 | R10: 45583 | S10: Sophie | T10: =TEXT(A10,"mmmm") -> October
A11: 45721 | B11: West | C11: Desk | D11: 5 | E11: 323.28 | F11: Store D | G11: Retail | H11: 0.1 | I11: Frank | J11: 1454.76 | K11: Gift Card | L11: SAVE10 | M11: 0 | N11: REG100009 | O11: Cust 3732 | P11: 41.1 | Q11: 45721 | R11: 45729 | S11: Wendy | T11: =TEXT(A11,"mmmm") -> March
A12: 45392 | B12: North | C12: Desk | D12: 15 | E12: 523.29 | F12: Store B | G12: Wholesale | H12: 0.15 | I12: Eva | J12: 6671.9475 | K12: Debit Card | M12: 0 | N12: REG100010 | O12: Cust 1462 | P12: 12.14 | Q12: 45392 | R12: 45399 | S12: Ryan | T12: =TEXT(A12,"mmmm") -> April
A13: 45485 | B13: East | C13: Phone | D13: 19 | E13: 207.35 | F13: Store D | G13: Retail | H13: 0.1 | I13: Eva | J13: 3545.685 | K13: Gift Card | M13: 1 | N13: REG100011 | O13: Cust 4330 | P13: 44.89 | Q13: 45485 | R13: 45491 | S13: Eric | T13: =TEXT(A13,"mmmm") -> July
A14: 45128 | B14: Central | C14: Phone | D14: 1 | E14: 120.53 | F14: Store B | G14: Retail | H14: 0.05 | I14: Diana | J14: 114.5035 | K14: Cash | L14: WINTER15 | M14: 0 | N14: REG100012 | O14: Cust 2372 | P14: 20.35 | Q14: 45128 | R14: 45138 | S14: Cameron | T14: =TEXT(A14,"mmmm") -> July
A15: 45675 | B15: West | C15: Tablet | D15: 1 | E15: 157.83 | F15: Store A | G15: Wholesale | H15: 0.15 | I15: Carlos | J15: 134.1555 | K15: Debit Card | M15: 0 | N15: REG100013 | O15: Cust 4672 | P15: 42.82 | Q15: 45675 | R15: 45679 | S15: Wendy | T15: =TEXT(A15,"mmmm") -> January
A16: 45634 | B16: North | C16: Desk | D16: 15 | E16: 220.3 | F16: Store B | G16: Retail | H16: 0.15 | I16: Diana | J16: 2808.825 | K16: Debit Card | M16: 0 | N16: REG100014 | O16: Cust 4548 | P16: 39.66 | Q16: 45634 | R16: 45641 | S16: Ryan | T16: =TEXT(A16,"mmmm") -> December
A17: 45788 | B17: West | C17: Chair | D17: 17 | E17: 162.96 | F17: Store A | G17: Wholesale | H17: 0.05 | I17: Eva | J17: 2631.804 | K17: Gift Card | L17: FREESHIP | M17: 0 | N17: REG100015 | O17: Cust 7037 | P17: 8.11 | Q17: 45788 | R17: 45794 | S17: Wendy | T17: =TEXT(A17,"mmmm") -> May
A18: 44983 | B18: West | C18: Laptop | D18: 19 | E18: 236.11 | F18: Store D | G18: Wholesale | H18: 0 | I18: Bob | J18: 4486.09 | K18: Online | L18: WINTER15 | M18: 0 | N18: REG100016 | O18: Cust 4975 | P18: 34.11 | Q18: 44983 | R18: 44989 | S18: Wendy | T18: =TEXT(A18,"mmmm") -> February
A19: 45440 | B19: Central | C19: Desk | D19: 11 | E19: 573.14 | F19: Store D | G19: Retail | H19: 0.05 | I19: Diana | J19: 5989.313 | K19: Cash | L19: SAVE10 | M19: 0 | N19: REG100017 | O19: Cust 8014 | P19: 34.71 | Q19: 45440 | R19: 45444 | S19: Cameron | T19: =TEXT(A19,"mmmm") -> May
A20: 45260 | B20: East | C20: Phone | D20: 20 | E20: 519.04 | F20: Store B | G20: Retail | H20: 0.15 | I20: Carlos | J20: 8823.68 | K20: Gift Card | L20: FREESHIP | M20: 0 | N20: REG100018 | O20: Cust 1228 | P20: 19.43 | Q20: 45260 | R20: 45268 | S20: Eric | T20: =TEXT(A20,"mmmm") -> November
A21: 45099 | B21: West | C21: Desk | D21: 14 | E21: 30.83 | F21: Store B | G21: Retail | H21: 0 | I21: Carlos | J21: 431.62 | K21: Online | L21: WINTER15 | M21: 1 | N21: REG100019 | O21: Cust 4247 | P21: 7.1 | Q21: 45099 | R21: 45109 | S21: Wendy | T21: =TEXT(A21,"mmmm") -> June
A22: 45813 | B22: West | C22: Phone | D22: 10 | E22: 319.05 | F22: Store D | G22: Wholesale | H22: 0 | I22: Diana | J22: 3190.5 | K22: Online | M22: 0 | N22: REG100020 | O22: Cust 4199 | P22: 28.43 | Q22: 45813 | R22: 45816 | S22: Wendy | T22: =TEXT(A22,"mmmm") -> June
A23: 44988 | B23: Central | C23: Chair | D23: 14 | E23: 312.79 | F23: Store A | G23: Retail | H23: 0.05 | I23: Bob | J23: 4160.107 | K23: Online | M23: 1 | N23: REG100021 | O23: Cust 4186 | P23: 46.83 | Q23: 44988 | R23: 44993 | S23: Cameron | T23: =TEXT(A23,"mmmm") -> March
A24: 45340 | B24: North | C24: Laptop | D24: 14 | E24: 395.45 | F24: Store C | G24: Retail | H24: 0 | I24: Carlos | J24: 5536.3 | K24: Cash | L24: FREESHIP | M24: 1 | N24: REG100022 | O24: Cust 8137 | P24: 36.45 | Q24: 45340 | R24: 45344 | S24: Ryan | T24: =TEXT(A24,"mmmm") -> February
A25: 45144 | B25: Central | C25: Laptop | D25: 12 | E25: 472.72 | F25: Store D | G25: Retail | H25: 0.15 | I25: Diana | J25: 4821.744 | K25: Credit Card | M25: 0 | N25: REG100023 | O25: Cust 4638 | P25: 27.97 | Q25: 45144 | R25: 45152 | S25: Cameron | T25: =TEXT(A25,"mmmm") -> August
A26: 45435 | B26: North | C26: Desk | D26: 5 | E26: 288.01 | F26: Store A | G26: Wholesale | H26: 0 | I26: Eva | J26: 1440.05 | K26: Credit Card | L26: FREESHIP | M26: 0 | N26: REG100024 | O26: Cust 8538 | P26: 46.69 | Q26: 45435 | R26: 45442 | S26: Ryan | T26: =TEXT(A26,"mmmm") -> May
A27: 45222 | B27: East | C27: Phone | D27: 13 | E27: 562.29 | F27: Store D | G27: Retail | H27: 0 | I27: Diana | J27: 7309.77 | K27: Gift Card | L27: SAVE10 | M27: 0 | N27: REG100025 | O27: Cust 6322 | P27: 38.13 | Q27: 45222 | R27: 45227 | S27: Eric | T27: =TEXT(A27,"mmmm") -> October
A28: 45824 | B28: West | C28: Phone | D28: 1 | E28: 101.73 | F28: Store D | G28: Retail | H28: 0 | I28: Frank | J28: 101.73 | K28: Debit Card | L28: WINTER15 | M28: 0 | N28: REG100026 | O28: Cust 2609 | P28: 11.59 | Q28: 45824 | R28: 45833 | S28: Wendy | T28: =TEXT(A28,"mmmm") -> June
A29: 44988 | B29: North | C29: Phone | D29: 4 | E29: 279.49 | F29: Store B | G29: Retail | H29: 0 | I29: Diana | J29: 1117.96 | K29: Credit Card | L29: FREESHIP | M29: 0 | N29: REG100027 | O29: Cust 6880 | P29: 24.78 | Q29: 44988 | R29: 44993 | S29: Ryan | T29: =TEXT(A29,"mmmm") -> March
A30: 45614 | B30: South | C30: Laptop | D30: 1 | E30: 178.55 | F30: Store A | G30: Retail | H30: 0.15 | I30: Carlos | J30: 151.7675 | K30: Debit Card | L30: SAVE10 | M30: 1 | N30: REG100028 | O30: Cust 1997 | P30: 7.61 | Q30: 45614 | R30: 45617 | S30: Sophie | T30: =TEXT(A30,"mmmm") -> November
A31: 45055 | B31: Central | C31: Tablet | D31: 1 | E31: 472.07 | F31: Store A | G31: Wholesale | H31: 0.1 | I31: Carlos | J31: 424.863 | K31: Online | L31: FREESHIP | M31: 0 | N31: REG100029 | O31: Cust 7072 | P31: 33.17 | Q31: 45055 | R31: 45063 | S31: Cameron | T31: =TEXT(A31,"mmmm") -> May
A32: 45633 | B32: North | C32: Tablet | D32: 12 | E32: 306.29 | F32: Store D | G32: Retail | H32: 0 | I32: Frank | J32: 3675.48 | K32: Debit Card | L32: SAVE10 | M32: 0 | N32: REG100030 | O32: Cust 7201 | P32: 37.38 | Q32: 45633 | R32: 45640 | S32: Ryan | T32: =TEXT(A32,"mmmm") -> December
A33: 45335 | B33: North | C33: Phone | D33: 7 | E33: 434.77 | F33: Store C | G33: Retail | H33: 0.15 | I33: Frank | J33: 2586.8815 | K33: Online | L33: SAVE10 | M33: 0 | N33: REG100031 | O33: Cust 9923 | P33: 12.35 | Q33: 45335 | R33: 45337 | S33: Ryan | T33: =TEXT(A33,"mmmm") -> February
A34: 45725 | B34: South | C34: Desk | D34: 6 | E34: 64.98 | F34: Store C | G34: Retail | H34: 0 | I34: Carlos | J34: 389.88 | K34: Debit Card | L34: WINTER15 | M34: 0 | N34: REG100032 | O34: Cust 2205 | P34: 21.25 | Q34: 45725 | R34: 45731 | S34: Sophie | T34: =TEXT(A34,"mmmm") -> March
A35: 45021 | B35: Central | C35: Desk | D35: 17 | E35: 476.49 | F35: Store D | G35: Retail | H35: 0 | I35: Alice | J35: 8100.33 | K35: Gift Card | M35: 0 | N35: REG100033 | O35: Cust 6403 | P35: 17.91 | Q35: 45021 | R35: 45027 | S35: Cameron | T35: =TEXT(A35,"mmmm") -> April
A36: 45785 | B36: North | C36: Monitor | D36: 4 | E36: 559.72 | F36: Store D | G36: Retail | H36: 0.15 | I36: Diana | J36: 1903.048 | K36: Online | L36: SAVE10 | M36: 0 | N36: REG100034 | O36: Cust 3953 | P36: 41.91 | Q36: 45785 | R36: 45789 | S36: Ryan | T36: =TEXT(A36,"mmmm") -> May
A37: 45172 | B37: North | C37: Tablet | D37: 14 | E37: 82.14 | F37: Store C | G37: Retail | H37: 0 | I37: Alice | J37: 1149.96 | K37: Credit Card | M37: 0 | N37: REG100035 | O37: Cust 7902 | P37: 12.57 | Q37: 45172 | R37: 45180 | S37: Ryan | T37: =TEXT(A37,"mmmm") -> September
A38: 45737 | B38: Central | C38: Chair | D38: 9 | E38: 343.21 | F38: Store A | G38: Retail | H38: 0.05 | I38: Carlos | J38: 2934.4455 | K38: Debit Card | L38: FREESHIP | M38: 0 | N38: REG100036 | O38: Cust 9968 | P38: 40.29 | Q38: 45737 | R38: 45744 | S38: Cameron | T38: =TEXT(A38,"mmmm") -> March
A39: 45828 | B39: South | C39: Chair | D39: 7 | E39: 301.01 | F39: Store B | G39: Retail | H39: 0.15 | I39: Diana | J39: 1791.0095 | K39: Cash | L39: SAVE10 | M39: 1 | N39: REG100037 | O39: Cust 3787 | P39: 34.97 | Q39: 45828 | R39: 45838 | S39: Sophie | T39: =TEXT(A39,"mmmm") -> June
A40: 45337 | B40: Central | C40: Printer | D40: 14 | E40: 428.13 | F40: Store C | G40: Retail | H40: 0.1 | I40: Bob | J40: 5394.438 | K40: Cash | M40: 1 | N40: REG100038 | O40: Cust 2469 | P40: 24.77 | Q40: 45337 | R40: 45347 | S40: Cameron | T40: =TEXT(A40,"mmmm") -> February
...

Sheet Sheet2
B2: Row Labels | C2: Sum of TotalPrice | E2: Row Labels | F2: Sum of TotalPrice | G2: Sum of Quantity
B3: January | C3: 35526.483 | E3: Chair | F3: 47507.756 | G3: 169
B4: February | C4: 37971.304 | E4: Desk | F4: 61269.576 | G4: 194
B5: March | C5: 41071.667 | E5: Laptop | F5: 55555.427 | G5: 188
B6: April | C6: 27095.969 | E6: Monitor | F6: 24137.04 | G6: 110
B7: May | C7: 36831.326 | E7: Phone | F7: 52564.61 | G7: 161
B8: June | C8: 22365.817 | E8: Printer | F8: 21996.18 | G8: 79
B9: July | C9: 26315.796 | E9: Tablet | F9: 53389.487 | G9: 170
B10: August | C10: 6938.184 | E10: Grand Total | F10: 316420.08 | G10: 1071
B11: September | C11: 6626.202
B12: October | C12: 27776.313
B13: November | C13: 26981.652
B14: December | C14: 20919.361
B15: Grand Total | C15: 316420.08
B17: Row Labels | C17: Sum of TotalPrice | E17: Region-Wise Sale's | G17: Total ORDERS
B18: Central | C18: 93552.871 | E18: East | F18: =SUMIF(Sheet1!B2:B101,"East",Sheet1!J2:J101) -> 56705.127 | G18: =COUNTIF(Sheet1!B$2:B$101,"East") -> 16
B19: East | C19: 56705.127 | E19: West | F19: =SUMIF(Sheet1!B2:B101,"West",Sheet1!J2:J101) -> 42490.722 | G19: =COUNTIF(Sheet1!B$2:B$101,"West") -> 17
B20: North | C20: 63998.012 | E20: North | F20: =SUMIF(Sheet1!B2:B101,"North",Sheet1!J2:J101) -> 63998.012 | G20: =COUNTIF(Sheet1!B$2:B$101,"North") -> 18
B21: South | C21: 59673.343 | E21: South | F21: =SUMIF(Sheet1!B2:B101,"South",Sheet1!J2:J101) -> 59673.343 | G21: =COUNTIF(Sheet1!B$2:B$101,"South") -> 21
B22: West | C22: 42490.722 | E22: Central | F22: =SUMIF(Sheet1!B2:B101,"Central",Sheet1!J2:J101) -> 93552.871 | G22: =COUNTIF(Sheet1!B$2:B$101,"Central") -> 28
B23: Grand Total | C23: 316420.08
